#VRML_SIM R2021b utf8
WorldInfo {
  defaultDamping Damping {
  }
  coordinateSystem "NUE"
}
Viewpoint {
  fieldOfView 0.7
  orientation 0.021325258282967177 0.8918194811741779 0.45188853311119226 3.548641337835795
  position -1.9502241605621071 7.174539108411085 -6.0552625602565895
}
PointLight {
  attenuation 0 0 1
  intensity 4
  location 0 0.3 0
}
Solid {
  translation 0 0.32 0
  children [
    PointLight {
      attenuation 0 0 1
      on FALSE
    }
    Shape {
      appearance PBRAppearance {
        roughness 1
        metalness 0
      }
      geometry Sphere {
        radius 0.1
      }
    }
  ]
  name "solid(2)"
  boundingObject Sphere {
    radius 0.1
  }
  physics Physics {
  }
}
Solid {
  translation 1.37782 0.32 0.618152
  children [
    PointLight {
      attenuation 0 0 1
      intensity 5
      on FALSE
    }
    Shape {
      appearance PBRAppearance {
        roughness 1
        metalness 0
      }
      geometry Sphere {
        radius 0.1
      }
    }
  ]
  name "solid(1)"
  boundingObject Sphere {
    radius 0.1
  }
  physics Physics {
  }
}
DirectionalLight {
  direction 0 -5 -10
  on FALSE
}
DirectionalLight {
  direction 10 -5 -5
  intensity 0.1
  on FALSE
}
DirectionalLight {
  direction -11 -5 -5
  intensity 0.1
  on FALSE
}
RectangleArena {
  translation 1.2 0 -0.57
  floorSize 10 4.5
}
DEF RobotLightC1 Robot {
  translation 3.6 0.04 -2.44
  children [
    Receiver {
      name "rec2"
      channel 2
    }
    Receiver {
      name "rec3"
      channel 3
    }
    Receiver {
      name "rec4"
      channel 4
    }
    Receiver {
      name "rec5"
      channel 5
    }
    Receiver {
      name "rec6"
      channel 6
    }
    Receiver {
      name "rec7"
      channel 7
    }
    Receiver {
      name "rec8"
      channel 8
    }
    Receiver {
      name "rec9"
      channel 9
    }
    Receiver {
      name "rec1"
      channel 10
    }
    Receiver {
      name "rec10"
      channel 11
    }
    Receiver {
      name "rec11"
      channel 12
    }
    Receiver {
      name "rec12"
      channel 13
    }
    Receiver {
      name "rec13"
      channel 14
    }
    Receiver {
      name "rec14"
      channel 15
    }
    Receiver {
      name "rec15"
      channel 14
    }
    Receiver {
      translation 1.75 0 0
      name "rec16"
      channel 17
    }
    Receiver {
      translation 1.75 0 0
      name "rec17"
      channel 18
    }
    Receiver {
      translation 1.75 0 0
      name "rec18"
      channel 19
    }
    Receiver {
      translation 1.75 0 0
      name "rec19"
      channel 20
    }
    Receiver {
      translation 1.75 0 0
      name "rec20"
      channel 21
    }
    Receiver {
      translation 1.75 0 0
      name "rec21"
      channel 22
    }
    Receiver {
      translation 1.75 0 0
      name "rec22"
      channel 23
    }
    Receiver {
      translation 1.75 0 0
      name "rec23"
      channel 24
    }
    Receiver {
      translation 1.75 0 0
      name "rec24"
      channel 25
    }
    Emitter {
      name "trans"
      range 1
      maxRange 1
      channel 1
    }
    Compass {
      name "com"
      yAxis FALSE
    }
    LightSensor {
      translation -0.02 0.04 0.02
      rotation 0 1 0 -2.35619
      children [
        DEF ls Shape {
          appearance Appearance {
            material Material {
              diffuseColor 1 1 0
            }
          }
          geometry Box {
            size 0.01 0.04 0.01
          }
        }
      ]
      name "ls1"
      boundingObject USE ls
      physics Physics {
      }
      occlusion TRUE
    }
    LightSensor {
      translation -0.02 0.04 -0.02
      rotation 0 1 0 -3.92699
      children [
        DEF ls Shape {
          appearance Appearance {
            material Material {
              diffuseColor 1 1 0
            }
          }
          geometry Box {
            size 0.01 0.04 0.01
          }
        }
      ]
      name "ls2"
      boundingObject USE ls
      physics Physics {
      }
      occlusion TRUE
    }
    LightSensor {
      translation 0.02 0.04 -0.02
      rotation 0 1 0 0.785398
      children [
        DEF ls Shape {
          appearance Appearance {
            material Material {
              diffuseColor 1 1 0
            }
          }
          geometry Box {
            size 0.01 0.04 0.01
          }
        }
      ]
      name "ls3"
      boundingObject USE ls
      physics Physics {
      }
      occlusion TRUE
    }
    LightSensor {
      translation 0.02 0.04 0.02
      rotation 0 1 0 -0.785398
      children [
        DEF ls Shape {
          appearance Appearance {
            material Material {
              diffuseColor 1 1 0
            }
          }
          geometry Box {
            size 0.01 0.04 0.01
          }
        }
      ]
      name "ls4"
      boundingObject USE ls
      physics Physics {
      }
      occlusion TRUE
    }
    DistanceSensor {
      translation 0 0 0.1
      rotation 0 1 0 -1.5708
      children [
        DEF DS Shape {
          appearance Appearance {
            material Material {
            }
          }
          geometry Box {
            size 0.01 0.01 0.01
          }
        }
      ]
      name "ds"
      boundingObject USE DS
      physics Physics {
      }
      lookupTable [
        0 0 0
        0.2 400 0
        0.5 1000 0
      ]
    }
    HingeJoint {
      jointParameters HingeJointParameters {
        anchor -0.06 0 -0.05
      }
      device [
        DEF wheel4 RotationalMotor {
          name "wheel4"
          acceleration 1
        }
      ]
      endPoint DEF WHEEL4 Solid {
        translation -0.05999991814307717 -9.632061444724494e-06 -0.05000362374001422
        rotation 0.03312248218235521 -0.03304576865397035 0.9989048394857981 1.571866762233069
        children [
          DEF WHEEL Shape {
            appearance Appearance {
              material Material {
                diffuseColor 0 0 1
              }
            }
            geometry Cylinder {
              height 0.02
              radius 0.04
            }
          }
        ]
        name "wheel4"
        boundingObject USE WHEEL
        physics DEF WHEEL_PH Physics {
        }
      }
    }
    HingeJoint {
      jointParameters HingeJointParameters {
        anchor 0.06 0 -0.05
      }
      device [
        DEF wheel3 RotationalMotor {
          name "wheel3"
          acceleration 1
        }
      ]
      endPoint DEF WHEEL3 Solid {
        translation 0.060000176302764274 -1.3570422243021472e-05 -0.04999976121740486
        rotation 0.033052858076168264 -0.03297527418051867 0.9989094753108093 1.5718690848001053
        children [
          DEF WHEEL Shape {
            appearance Appearance {
              material Material {
                diffuseColor 0 0 1
              }
            }
            geometry Cylinder {
              height 0.02
              radius 0.04
            }
          }
        ]
        name "wheel3"
        boundingObject USE WHEEL
        physics USE WHEEL_PH
      }
    }
    HingeJoint {
      jointParameters HingeJointParameters {
        anchor -0.06 0 0.05
      }
      device [
        DEF wheel2 RotationalMotor {
          name "wheel2"
          acceleration 1
        }
      ]
      endPoint DEF WHEEL2 Solid {
        translation -0.060002157958187 -8.7540512070535e-06 0.049996310781291034
        rotation 0.033122390039492314 -0.03304586831487273 0.9989048392441533 1.5718664036508943
        children [
          DEF WHEEL Shape {
            appearance Appearance {
              material Material {
                diffuseColor 0 0 1
              }
            }
            geometry Cylinder {
              height 0.02
              radius 0.04
            }
          }
        ]
        name "wheel2"
        boundingObject USE WHEEL
        physics DEF WHEEL_PH Physics {
        }
      }
    }
    DEF BODY Shape {
      appearance Appearance {
        material Material {
          diffuseColor 1 0 0
        }
      }
      geometry Box {
        size 0.1 0.05 0.2
      }
    }
    HingeJoint {
      jointParameters HingeJointParameters {
        anchor 0.06 0 0.05
      }
      device [
        DEF wheel1 RotationalMotor {
          name "wheel1"
        }
      ]
      endPoint DEF WHEEL1 Solid {
        translation 0.06000190297626937 6.2227360664119e-06 0.049995882054905696
        rotation -0.04651496824615402 0.046637305478202655 -0.9978283015964179 4.710224110905362
        children [
          DEF WHEEL Shape {
            appearance Appearance {
              material Material {
                diffuseColor 0 0 1
              }
            }
            geometry Cylinder {
              height 0.02
              radius 0.04
            }
          }
        ]
        name "wheel1"
        boundingObject USE WHEEL
        physics USE WHEEL_PH
      }
    }
  ]
  name "RL0"
  boundingObject USE BODY
  physics Physics {
  }
  controller "AgentController_v0"
}
DEF RobotLightC11 Robot {
  translation 2.13 0.04 -2.49
  children [
    Receiver {
      name "rec2"
      channel 2
    }
    Receiver {
      name "rec3"
      channel 3
    }
    Receiver {
      name "rec4"
      channel 4
    }
    Receiver {
      name "rec5"
      channel 5
    }
    Receiver {
      name "rec6"
      channel 6
    }
    Receiver {
      name "rec7"
      channel 7
    }
    Receiver {
      name "rec8"
      channel 8
    }
    Receiver {
      name "rec9"
      channel 9
    }
    Receiver {
      name "rec1"
      channel 10
    }
    Receiver {
      name "rec10"
      channel 1
    }
    Receiver {
      name "rec11"
      channel 12
    }
    Receiver {
      name "rec12"
      channel 13
    }
    Receiver {
      name "rec13"
      channel 14
    }
    Receiver {
      name "rec14"
      channel 15
    }
    Receiver {
      name "rec15"
      channel 14
    }
    Receiver {
      translation 1.75 0 0
      name "rec16"
      channel 17
    }
    Receiver {
      translation 1.75 0 0
      name "rec17"
      channel 18
    }
    Receiver {
      translation 1.75 0 0
      name "rec18"
      channel 19
    }
    Receiver {
      translation 1.75 0 0
      name "rec19"
      channel 20
    }
    Receiver {
      translation 1.75 0 0
      name "rec20"
      channel 21
    }
    Receiver {
      translation 1.75 0 0
      name "rec21"
      channel 22
    }
    Receiver {
      translation 1.75 0 0
      name "rec22"
      channel 23
    }
    Receiver {
      translation 1.75 0 0
      name "rec23"
      channel 24
    }
    Receiver {
      translation 1.75 0 0
      name "rec24"
      channel 25
    }
    Emitter {
      translation -0.5 0 0
      name "trans"
      range 1
      maxRange 1
      channel 11
    }
    Compass {
      name "com"
      yAxis FALSE
    }
    LightSensor {
      translation -0.02 0.04 0.02
      rotation 0 1 0 -2.35619
      children [
        DEF ls Shape {
          appearance Appearance {
            material Material {
              diffuseColor 1 1 0
            }
          }
          geometry Box {
            size 0.01 0.04 0.01
          }
        }
      ]
      name "ls1"
      boundingObject USE ls
      physics Physics {
      }
      occlusion TRUE
    }
    LightSensor {
      translation -0.02 0.04 -0.02
      rotation 0 1 0 -3.92699
      children [
        DEF ls Shape {
          appearance Appearance {
            material Material {
              diffuseColor 1 1 0
            }
          }
          geometry Box {
            size 0.01 0.04 0.01
          }
        }
      ]
      name "ls2"
      boundingObject USE ls
      physics Physics {
      }
      occlusion TRUE
    }
    LightSensor {
      translation 0.02 0.04 -0.02
      rotation 0 1 0 0.785398
      children [
        DEF ls Shape {
          appearance Appearance {
            material Material {
              diffuseColor 1 1 0
            }
          }
          geometry Box {
            size 0.01 0.04 0.01
          }
        }
      ]
      name "ls3"
      boundingObject USE ls
      physics Physics {
      }
      occlusion TRUE
    }
    LightSensor {
      translation 0.02 0.04 0.02
      rotation 0 1 0 -0.785398
      children [
        DEF ls Shape {
          appearance Appearance {
            material Material {
              diffuseColor 1 1 0
            }
          }
          geometry Box {
            size 0.01 0.04 0.01
          }
        }
      ]
      name "ls4"
      boundingObject USE ls
      physics Physics {
      }
      occlusion TRUE
    }
    DistanceSensor {
      translation 0 0 0.1
      rotation 0 1 0 -1.5708
      children [
        DEF DS Shape {
          appearance Appearance {
            material Material {
            }
          }
          geometry Box {
            size 0.01 0.01 0.01
          }
        }
      ]
      name "ds"
      boundingObject USE DS
      physics Physics {
      }
      lookupTable [
        0 0 0
        0.2 400 0
        0.5 1000 0
      ]
    }
    HingeJoint {
      jointParameters HingeJointParameters {
        anchor -0.06 0 -0.05
      }
      device [
        DEF wheel4 RotationalMotor {
          name "wheel4"
          acceleration 1
        }
      ]
      endPoint DEF WHEEL4 Solid {
        translation -0.05999991814307717 -9.632061444724494e-06 -0.05000362374001422
        rotation 0.03312248218235521 -0.03304576865397035 0.9989048394857981 1.571866762233069
        children [
          DEF WHEEL Shape {
            appearance Appearance {
              material Material {
                diffuseColor 0 0 1
              }
            }
            geometry Cylinder {
              height 0.02
              radius 0.04
            }
          }
        ]
        name "wheel4"
        boundingObject USE WHEEL
        physics DEF WHEEL_PH Physics {
        }
      }
    }
    HingeJoint {
      jointParameters HingeJointParameters {
        anchor 0.06 0 -0.05
      }
      device [
        DEF wheel3 RotationalMotor {
          name "wheel3"
          acceleration 1
        }
      ]
      endPoint DEF WHEEL3 Solid {
        translation 0.060000176302764274 -1.3570422243021472e-05 -0.04999976121740486
        rotation 0.033052858076168264 -0.03297527418051867 0.9989094753108093 1.5718690848001053
        children [
          DEF WHEEL Shape {
            appearance Appearance {
              material Material {
                diffuseColor 0 0 1
              }
            }
            geometry Cylinder {
              height 0.02
              radius 0.04
            }
          }
        ]
        name "wheel3"
        boundingObject USE WHEEL
        physics USE WHEEL_PH
      }
    }
    HingeJoint {
      jointParameters HingeJointParameters {
        anchor -0.06 0 0.05
      }
      device [
        DEF wheel2 RotationalMotor {
          name "wheel2"
          acceleration 1
        }
      ]
      endPoint DEF WHEEL2 Solid {
        translation -0.060002157958187 -8.7540512070535e-06 0.049996310781291034
        rotation 0.033122390039492314 -0.03304586831487273 0.9989048392441533 1.5718664036508943
        children [
          DEF WHEEL Shape {
            appearance Appearance {
              material Material {
                diffuseColor 0 0 1
              }
            }
            geometry Cylinder {
              height 0.02
              radius 0.04
            }
          }
        ]
        name "wheel2"
        boundingObject USE WHEEL
        physics DEF WHEEL_PH Physics {
        }
      }
    }
    DEF BODY Shape {
      appearance Appearance {
        material Material {
          diffuseColor 1 0 0
        }
      }
      geometry Box {
        size 0.1 0.05 0.2
      }
    }
    HingeJoint {
      jointParameters HingeJointParameters {
        anchor 0.06 0 0.05
      }
      device [
        DEF wheel1 RotationalMotor {
          name "wheel1"
        }
      ]
      endPoint DEF WHEEL1 Solid {
        translation 0.06000190297626937 6.2227360664119e-06 0.049995882054905696
        rotation -0.04651496824615402 0.046637305478202655 -0.9978283015964179 4.710224110905362
        children [
          DEF WHEEL Shape {
            appearance Appearance {
              material Material {
                diffuseColor 0 0 1
              }
            }
            geometry Cylinder {
              height 0.02
              radius 0.04
            }
          }
        ]
        name "wheel1"
        boundingObject USE WHEEL
        physics USE WHEEL_PH
      }
    }
  ]
  name "RL10"
  boundingObject USE BODY
  physics Physics {
  }
  controller "AgentController_v0"
}
DEF RobotLightC2 Robot {
  translation -0.35 0.04 -2.5
  children [
    Receiver {
      name "rec1"
      channel 1
    }
    Receiver {
      name "rec3"
      channel 3
    }
    Receiver {
      name "rec4"
      channel 4
    }
    Receiver {
      name "rec5"
      channel 5
    }
    Receiver {
      name "rec6"
      channel 6
    }
    Receiver {
      name "rec7"
      channel 7
    }
    Receiver {
      name "rec8"
      channel 8
    }
    Receiver {
      name "rec9"
      channel 9
    }
    Receiver {
      name "rec2"
      channel 10
    }
    Receiver {
      name "rec10"
      channel 11
    }
    Receiver {
      name "rec11"
      channel 12
    }
    Receiver {
      name "rec12"
      channel 13
    }
    Receiver {
      name "rec13"
      channel 14
    }
    Receiver {
      name "rec14"
      channel 15
    }
    Receiver {
      name "rec15"
      channel 14
    }
    Receiver {
      translation 1.75 0 0
      name "rec16"
      channel 17
    }
    Receiver {
      translation 1.75 0 0
      name "rec17"
      channel 18
    }
    Receiver {
      translation 1.75 0 0
      name "rec18"
      channel 19
    }
    Receiver {
      translation 1.75 0 0
      name "rec19"
      channel 20
    }
    Receiver {
      translation 1.75 0 0
      name "rec20"
      channel 21
    }
    Receiver {
      translation 1.75 0 0
      name "rec21"
      channel 22
    }
    Receiver {
      translation 1.75 0 0
      name "rec22"
      channel 23
    }
    Receiver {
      translation 1.75 0 0
      name "rec23"
      channel 24
    }
    Receiver {
      translation 1.75 0 0
      name "rec24"
      channel 25
    }
    Emitter {
      name "trans"
      range 1
      maxRange 1
      channel 2
    }
    Compass {
      name "com"
      yAxis FALSE
    }
    LightSensor {
      translation -0.02 0.04 0.02
      rotation 0 1 0 -2.35619
      children [
        DEF ls Shape {
          appearance Appearance {
            material Material {
              diffuseColor 1 1 0
            }
          }
          geometry Box {
            size 0.01 0.04 0.01
          }
        }
      ]
      name "ls1"
      boundingObject USE ls
      physics Physics {
      }
      occlusion TRUE
    }
    LightSensor {
      translation -0.02 0.04 -0.02
      rotation 0 1 0 -3.92699
      children [
        DEF ls Shape {
          appearance Appearance {
            material Material {
              diffuseColor 1 1 0
            }
          }
          geometry Box {
            size 0.01 0.04 0.01
          }
        }
      ]
      name "ls2"
      boundingObject USE ls
      physics Physics {
      }
      occlusion TRUE
    }
    LightSensor {
      translation 0.02 0.04 -0.02
      rotation 0 1 0 0.785398
      children [
        DEF ls Shape {
          appearance Appearance {
            material Material {
              diffuseColor 1 1 0
            }
          }
          geometry Box {
            size 0.01 0.04 0.01
          }
        }
      ]
      name "ls3"
      boundingObject USE ls
      physics Physics {
      }
      occlusion TRUE
    }
    LightSensor {
      translation 0.02 0.04 0.02
      rotation 0 1 0 -0.785398
      children [
        DEF ls Shape {
          appearance Appearance {
            material Material {
              diffuseColor 1 1 0
            }
          }
          geometry Box {
            size 0.01 0.04 0.01
          }
        }
      ]
      name "ls4"
      boundingObject USE ls
      physics Physics {
      }
      occlusion TRUE
    }
    DistanceSensor {
      translation 0 0 0.1
      rotation 0 1 0 -1.5708
      children [
        DEF DS Shape {
          appearance Appearance {
            material Material {
            }
          }
          geometry Box {
            size 0.01 0.01 0.01
          }
        }
      ]
      name "ds"
      boundingObject USE DS
      physics Physics {
      }
      lookupTable [
        0 0 0
        0.2 400 0
        0.5 1000 0
      ]
    }
    HingeJoint {
      jointParameters HingeJointParameters {
        anchor -0.06 0 -0.05
      }
      device [
        DEF wheel4 RotationalMotor {
          name "wheel4"
          acceleration 1
        }
      ]
      endPoint DEF WHEEL4 Solid {
        translation -0.05999991814307717 -9.632061444724495e-06 -0.05000362374001422
        rotation 0.03312248218235521 -0.03304576865397035 0.9989048394857979 1.5718667622330686
        children [
          DEF WHEEL Shape {
            appearance Appearance {
              material Material {
                diffuseColor 0 0 1
              }
            }
            geometry Cylinder {
              height 0.02
              radius 0.04
            }
          }
        ]
        name "wheel4"
        boundingObject USE WHEEL
        physics DEF WHEEL_PH Physics {
        }
      }
    }
    HingeJoint {
      jointParameters HingeJointParameters {
        anchor 0.06 0 -0.05
      }
      device [
        DEF wheel3 RotationalMotor {
          name "wheel3"
          acceleration 1
        }
      ]
      endPoint DEF WHEEL3 Solid {
        translation 0.060000176302764274 -1.357042224302147e-05 -0.04999976121740486
        rotation 0.033052858076168264 -0.03297527418051867 0.9989094753108093 1.5718690848001053
        children [
          DEF WHEEL Shape {
            appearance Appearance {
              material Material {
                diffuseColor 0 0 1
              }
            }
            geometry Cylinder {
              height 0.02
              radius 0.04
            }
          }
        ]
        name "wheel3"
        boundingObject USE WHEEL
        physics USE WHEEL_PH
      }
    }
    HingeJoint {
      jointParameters HingeJointParameters {
        anchor -0.06 0 0.05
      }
      device [
        DEF wheel2 RotationalMotor {
          name "wheel2"
          acceleration 1
        }
      ]
      endPoint DEF WHEEL2 Solid {
        translation -0.060002157958187 -8.754051207053491e-06 0.049996310781291034
        rotation 0.03312239003949233 -0.033045868314872745 0.9989048392441533 1.5718664036508943
        children [
          DEF WHEEL Shape {
            appearance Appearance {
              material Material {
                diffuseColor 0 0 1
              }
            }
            geometry Cylinder {
              height 0.02
              radius 0.04
            }
          }
        ]
        name "wheel2"
        boundingObject USE WHEEL
        physics DEF WHEEL_PH Physics {
        }
      }
    }
    DEF BODY Shape {
      appearance Appearance {
        material Material {
          diffuseColor 1 0 0
        }
      }
      geometry Box {
        size 0.1 0.05 0.2
      }
    }
    HingeJoint {
      jointParameters HingeJointParameters {
        anchor 0.06 0 0.05
      }
      device [
        DEF wheel1 RotationalMotor {
          name "wheel1"
        }
      ]
      endPoint DEF WHEEL1 Solid {
        translation 0.06000190297626937 6.22273606641257e-06 0.049995882054905696
        rotation -0.04651496824615403 0.0466373054782027 -0.9978283015964179 4.710224110905362
        children [
          DEF WHEEL Shape {
            appearance Appearance {
              material Material {
                diffuseColor 0 0 1
              }
            }
            geometry Cylinder {
              height 0.02
              radius 0.04
            }
          }
        ]
        name "wheel1"
        boundingObject USE WHEEL
        physics USE WHEEL_PH
      }
    }
  ]
  name "RL1"
  boundingObject USE BODY
  physics Physics {
  }
  controller "AgentController_v0"
}
DEF RobotLightC3 Robot {
  translation 0.11 0.04 -2.51
  children [
    Receiver {
      name "rec1"
      channel 1
    }
    Receiver {
      name "rec2"
      channel 2
    }
    Receiver {
      name "rec4"
      channel 4
    }
    Receiver {
      name "rec5"
      channel 5
    }
    Receiver {
      name "rec6"
      channel 6
    }
    Receiver {
      name "rec7"
      channel 7
    }
    Receiver {
      name "rec8"
      channel 8
    }
    Receiver {
      name "rec9"
      channel 9
    }
    Receiver {
      name "rec3"
      channel 10
    }
    Receiver {
      name "rec10"
      channel 11
    }
    Receiver {
      name "rec11"
      channel 12
    }
    Receiver {
      name "rec12"
      channel 13
    }
    Receiver {
      name "rec13"
      channel 14
    }
    Receiver {
      name "rec14"
      channel 15
    }
    Receiver {
      name "rec15"
      channel 14
    }
    Receiver {
      translation 1.75 0 0
      name "rec16"
      channel 17
    }
    Receiver {
      translation 1.75 0 0
      name "rec17"
      channel 18
    }
    Receiver {
      translation 1.75 0 0
      name "rec18"
      channel 19
    }
    Receiver {
      translation 1.75 0 0
      name "rec19"
      channel 20
    }
    Receiver {
      translation 1.75 0 0
      name "rec20"
      channel 21
    }
    Receiver {
      translation 1.75 0 0
      name "rec21"
      channel 22
    }
    Receiver {
      translation 1.75 0 0
      name "rec22"
      channel 23
    }
    Receiver {
      translation 1.75 0 0
      name "rec23"
      channel 24
    }
    Receiver {
      translation 1.75 0 0
      name "rec24"
      channel 25
    }
    Emitter {
      name "trans"
      range 1
      maxRange 1
      channel 4
    }
    Compass {
      name "com"
      yAxis FALSE
    }
    LightSensor {
      translation -0.02 0.04 0.02
      rotation 0 1 0 -2.35619
      children [
        DEF ls Shape {
          appearance Appearance {
            material Material {
              diffuseColor 1 1 0
            }
          }
          geometry Box {
            size 0.01 0.04 0.01
          }
        }
      ]
      name "ls1"
      boundingObject USE ls
      physics Physics {
      }
      occlusion TRUE
    }
    LightSensor {
      translation -0.02 0.04 -0.02
      rotation 0 1 0 -3.92699
      children [
        DEF ls Shape {
          appearance Appearance {
            material Material {
              diffuseColor 1 1 0
            }
          }
          geometry Box {
            size 0.01 0.04 0.01
          }
        }
      ]
      name "ls2"
      boundingObject USE ls
      physics Physics {
      }
      occlusion TRUE
    }
    LightSensor {
      translation 0.02 0.04 -0.02
      rotation 0 1 0 0.785398
      children [
        DEF ls Shape {
          appearance Appearance {
            material Material {
              diffuseColor 1 1 0
            }
          }
          geometry Box {
            size 0.01 0.04 0.01
          }
        }
      ]
      name "ls3"
      boundingObject USE ls
      physics Physics {
      }
      occlusion TRUE
    }
    LightSensor {
      translation 0.02 0.04 0.02
      rotation 0 1 0 -0.785398
      children [
        DEF ls Shape {
          appearance Appearance {
            material Material {
              diffuseColor 1 1 0
            }
          }
          geometry Box {
            size 0.01 0.04 0.01
          }
        }
      ]
      name "ls4"
      boundingObject USE ls
      physics Physics {
      }
      occlusion TRUE
    }
    DistanceSensor {
      translation 0 0 0.1
      rotation 0 1 0 -1.5708
      children [
        DEF DS Shape {
          appearance Appearance {
            material Material {
            }
          }
          geometry Box {
            size 0.01 0.01 0.01
          }
        }
      ]
      name "ds"
      boundingObject USE DS
      physics Physics {
      }
      lookupTable [
        0 0 0
        0.2 400 0
        0.5 1000 0
      ]
    }
    HingeJoint {
      jointParameters HingeJointParameters {
        anchor -0.06 0 -0.05
      }
      device [
        DEF wheel4 RotationalMotor {
          name "wheel4"
          acceleration 1
        }
      ]
      endPoint DEF WHEEL4 Solid {
        translation -0.05999991814307717 -9.632061444724495e-06 -0.05000362374001422
        rotation 0.0331224821823552 -0.03304576865397035 0.9989048394857979 1.5718667622330686
        children [
          DEF WHEEL Shape {
            appearance Appearance {
              material Material {
                diffuseColor 0 0 1
              }
            }
            geometry Cylinder {
              height 0.02
              radius 0.04
            }
          }
        ]
        name "wheel4"
        boundingObject USE WHEEL
        physics DEF WHEEL_PH Physics {
        }
      }
    }
    HingeJoint {
      jointParameters HingeJointParameters {
        anchor 0.06 0 -0.05
      }
      device [
        DEF wheel3 RotationalMotor {
          name "wheel3"
          acceleration 1
        }
      ]
      endPoint DEF WHEEL3 Solid {
        translation 0.060000176302764274 -1.357042224302147e-05 -0.04999976121740486
        rotation 0.033052858076168264 -0.03297527418051867 0.9989094753108093 1.5718690848001053
        children [
          DEF WHEEL Shape {
            appearance Appearance {
              material Material {
                diffuseColor 0 0 1
              }
            }
            geometry Cylinder {
              height 0.02
              radius 0.04
            }
          }
        ]
        name "wheel3"
        boundingObject USE WHEEL
        physics USE WHEEL_PH
      }
    }
    HingeJoint {
      jointParameters HingeJointParameters {
        anchor -0.06 0 0.05
      }
      device [
        DEF wheel2 RotationalMotor {
          name "wheel2"
          acceleration 1
        }
      ]
      endPoint DEF WHEEL2 Solid {
        translation -0.060002157958187 -8.75405120705349e-06 0.049996310781291034
        rotation 0.03312239003949233 -0.033045868314872745 0.9989048392441533 1.5718664036508943
        children [
          DEF WHEEL Shape {
            appearance Appearance {
              material Material {
                diffuseColor 0 0 1
              }
            }
            geometry Cylinder {
              height 0.02
              radius 0.04
            }
          }
        ]
        name "wheel2"
        boundingObject USE WHEEL
        physics DEF WHEEL_PH Physics {
        }
      }
    }
    DEF BODY Shape {
      appearance Appearance {
        material Material {
          diffuseColor 1 0 0
        }
      }
      geometry Box {
        size 0.1 0.05 0.2
      }
    }
    HingeJoint {
      jointParameters HingeJointParameters {
        anchor 0.06 0 0.05
      }
      device [
        DEF wheel1 RotationalMotor {
          name "wheel1"
        }
      ]
      endPoint DEF WHEEL1 Solid {
        translation 0.06000190297626937 6.222736066412576e-06 0.049995882054905696
        rotation -0.046514968246154025 0.04663730547820269 -0.9978283015964179 4.710224110905362
        children [
          DEF WHEEL Shape {
            appearance Appearance {
              material Material {
                diffuseColor 0 0 1
              }
            }
            geometry Cylinder {
              height 0.02
              radius 0.04
            }
          }
        ]
        name "wheel1"
        boundingObject USE WHEEL
        physics USE WHEEL_PH
      }
    }
  ]
  name "RL2"
  boundingObject USE BODY
  physics Physics {
  }
  controller "AgentController_v0"
}
DEF RobotLightC4 Robot {
  translation 1.09 0.04 -2.47
  children [
    Receiver {
      name "rec1"
      channel 1
    }
    Receiver {
      name "rec2"
      channel 2
    }
    Receiver {
      name "rec3"
      channel 3
    }
    Receiver {
      name "rec5"
      channel 5
    }
    Receiver {
      name "rec6"
      channel 6
    }
    Receiver {
      name "rec7"
      channel 7
    }
    Receiver {
      name "rec8"
      channel 8
    }
    Receiver {
      name "rec9"
      channel 9
    }
    Receiver {
      name "rec4"
      channel 10
    }
    Receiver {
      name "rec10"
      channel 11
    }
    Receiver {
      name "rec11"
      channel 12
    }
    Receiver {
      name "rec12"
      channel 13
    }
    Receiver {
      name "rec13"
      channel 14
    }
    Receiver {
      name "rec14"
      channel 15
    }
    Receiver {
      name "rec15"
      channel 14
    }
    Receiver {
      translation 1.75 0 0
      name "rec16"
      channel 17
    }
    Receiver {
      translation 1.75 0 0
      name "rec17"
      channel 18
    }
    Receiver {
      translation 1.75 0 0
      name "rec18"
      channel 19
    }
    Receiver {
      translation 1.75 0 0
      name "rec19"
      channel 20
    }
    Receiver {
      translation 1.75 0 0
      name "rec20"
      channel 21
    }
    Receiver {
      translation 1.75 0 0
      name "rec21"
      channel 22
    }
    Receiver {
      translation 1.75 0 0
      name "rec22"
      channel 23
    }
    Receiver {
      translation 1.75 0 0
      name "rec23"
      channel 24
    }
    Receiver {
      translation 1.75 0 0
      name "rec24"
      channel 25
    }
    Emitter {
      name "trans"
      range 1
      maxRange 1
      channel 4
    }
    Compass {
      name "com"
      yAxis FALSE
    }
    LightSensor {
      translation -0.02 0.04 0.02
      rotation 0 1 0 -2.35619
      children [
        DEF ls Shape {
          appearance Appearance {
            material Material {
              diffuseColor 1 1 0
            }
          }
          geometry Box {
            size 0.01 0.04 0.01
          }
        }
      ]
      name "ls1"
      boundingObject USE ls
      physics Physics {
      }
      occlusion TRUE
    }
    LightSensor {
      translation -0.02 0.04 -0.02
      rotation 0 1 0 -3.92699
      children [
        DEF ls Shape {
          appearance Appearance {
            material Material {
              diffuseColor 1 1 0
            }
          }
          geometry Box {
            size 0.01 0.04 0.01
          }
        }
      ]
      name "ls2"
      boundingObject USE ls
      physics Physics {
      }
      occlusion TRUE
    }
    LightSensor {
      translation 0.02 0.04 -0.02
      rotation 0 1 0 0.785398
      children [
        DEF ls Shape {
          appearance Appearance {
            material Material {
              diffuseColor 1 1 0
            }
          }
          geometry Box {
            size 0.01 0.04 0.01
          }
        }
      ]
      name "ls3"
      boundingObject USE ls
      physics Physics {
      }
      occlusion TRUE
    }
    LightSensor {
      translation 0.02 0.04 0.02
      rotation 0 1 0 -0.785398
      children [
        DEF ls Shape {
          appearance Appearance {
            material Material {
              diffuseColor 1 1 0
            }
          }
          geometry Box {
            size 0.01 0.04 0.01
          }
        }
      ]
      name "ls4"
      boundingObject USE ls
      physics Physics {
      }
      occlusion TRUE
    }
    DistanceSensor {
      translation 0 0 0.1
      rotation 0 1 0 -1.5708
      children [
        DEF DS Shape {
          appearance Appearance {
            material Material {
            }
          }
          geometry Box {
            size 0.01 0.01 0.01
          }
        }
      ]
      name "ds"
      boundingObject USE DS
      physics Physics {
      }
      lookupTable [
        0 0 0
        0.2 400 0
        0.5 1000 0
      ]
    }
    HingeJoint {
      jointParameters HingeJointParameters {
        anchor -0.06 0 -0.05
      }
      device [
        DEF wheel4 RotationalMotor {
          name "wheel4"
          acceleration 1
        }
      ]
      endPoint DEF WHEEL4 Solid {
        translation -0.05999991814307717 -9.632061444724495e-06 -0.05000362374001422
        rotation 0.0331224821823552 -0.03304576865397035 0.9989048394857979 1.5718667622330686
        children [
          DEF WHEEL Shape {
            appearance Appearance {
              material Material {
                diffuseColor 0 0 1
              }
            }
            geometry Cylinder {
              height 0.02
              radius 0.04
            }
          }
        ]
        name "wheel4"
        boundingObject USE WHEEL
        physics DEF WHEEL_PH Physics {
        }
      }
    }
    HingeJoint {
      jointParameters HingeJointParameters {
        anchor 0.06 0 -0.05
      }
      device [
        DEF wheel3 RotationalMotor {
          name "wheel3"
          acceleration 1
        }
      ]
      endPoint DEF WHEEL3 Solid {
        translation 0.060000176302764274 -1.357042224302147e-05 -0.04999976121740486
        rotation 0.033052858076168264 -0.03297527418051867 0.9989094753108093 1.5718690848001053
        children [
          DEF WHEEL Shape {
            appearance Appearance {
              material Material {
                diffuseColor 0 0 1
              }
            }
            geometry Cylinder {
              height 0.02
              radius 0.04
            }
          }
        ]
        name "wheel3"
        boundingObject USE WHEEL
        physics USE WHEEL_PH
      }
    }
    HingeJoint {
      jointParameters HingeJointParameters {
        anchor -0.06 0 0.05
      }
      device [
        DEF wheel2 RotationalMotor {
          name "wheel2"
          acceleration 1
        }
      ]
      endPoint DEF WHEEL2 Solid {
        translation -0.060002157958187 -8.754051207053491e-06 0.049996310781291034
        rotation 0.033122390039492314 -0.033045868314872745 0.9989048392441533 1.5718664036508943
        children [
          DEF WHEEL Shape {
            appearance Appearance {
              material Material {
                diffuseColor 0 0 1
              }
            }
            geometry Cylinder {
              height 0.02
              radius 0.04
            }
          }
        ]
        name "wheel2"
        boundingObject USE WHEEL
        physics DEF WHEEL_PH Physics {
        }
      }
    }
    DEF BODY Shape {
      appearance Appearance {
        material Material {
          diffuseColor 1 0 0
        }
      }
      geometry Box {
        size 0.1 0.05 0.2
      }
    }
    HingeJoint {
      jointParameters HingeJointParameters {
        anchor 0.06 0 0.05
      }
      device [
        DEF wheel1 RotationalMotor {
          name "wheel1"
        }
      ]
      endPoint DEF WHEEL1 Solid {
        translation 0.06000190297626937 6.222736066412571e-06 0.049995882054905696
        rotation -0.04651496824615403 0.0466373054782027 -0.9978283015964179 4.710224110905362
        children [
          DEF WHEEL Shape {
            appearance Appearance {
              material Material {
                diffuseColor 0 0 1
              }
            }
            geometry Cylinder {
              height 0.02
              radius 0.04
            }
          }
        ]
        name "wheel1"
        boundingObject USE WHEEL
        physics USE WHEEL_PH
      }
    }
  ]
  name "RL3"
  boundingObject USE BODY
  physics Physics {
  }
  controller "AgentController_v0"
}
DEF RobotLightC5 Robot {
  translation 0.58 0.04 -2.52
  children [
    Receiver {
      name "rec1"
      channel 1
    }
    Receiver {
      name "rec2"
      channel 2
    }
    Receiver {
      name "rec3"
      channel 3
    }
    Receiver {
      name "rec4"
      channel 4
    }
    Receiver {
      name "rec6"
      channel 6
    }
    Receiver {
      name "rec7"
      channel 7
    }
    Receiver {
      name "rec8"
      channel 8
    }
    Receiver {
      name "rec9"
      channel 9
    }
    Receiver {
      name "rec5"
      channel 10
    }
    Receiver {
      name "rec10"
      channel 11
    }
    Receiver {
      name "rec11"
      channel 12
    }
    Receiver {
      name "rec12"
      channel 13
    }
    Receiver {
      name "rec13"
      channel 14
    }
    Receiver {
      name "rec14"
      channel 15
    }
    Receiver {
      name "rec15"
      channel 14
    }
    Receiver {
      translation 1.75 0 0
      name "rec16"
      channel 17
    }
    Receiver {
      translation 1.75 0 0
      name "rec17"
      channel 18
    }
    Receiver {
      translation 1.75 0 0
      name "rec18"
      channel 19
    }
    Receiver {
      translation 1.75 0 0
      name "rec19"
      channel 20
    }
    Receiver {
      translation 1.75 0 0
      name "rec20"
      channel 21
    }
    Receiver {
      translation 1.75 0 0
      name "rec21"
      channel 22
    }
    Receiver {
      translation 1.75 0 0
      name "rec22"
      channel 23
    }
    Receiver {
      translation 1.75 0 0
      name "rec23"
      channel 24
    }
    Receiver {
      translation 1.75 0 0
      name "rec24"
      channel 25
    }
    Emitter {
      name "trans"
      range 1
      maxRange 1
      channel 5
    }
    Compass {
      name "com"
      yAxis FALSE
    }
    LightSensor {
      translation -0.02 0.04 0.02
      rotation 0 1 0 -2.35619
      children [
        DEF ls Shape {
          appearance Appearance {
            material Material {
              diffuseColor 1 1 0
            }
          }
          geometry Box {
            size 0.01 0.04 0.01
          }
        }
      ]
      name "ls1"
      boundingObject USE ls
      physics Physics {
      }
      occlusion TRUE
    }
    LightSensor {
      translation -0.02 0.04 -0.02
      rotation 0 1 0 -3.92699
      children [
        DEF ls Shape {
          appearance Appearance {
            material Material {
              diffuseColor 1 1 0
            }
          }
          geometry Box {
            size 0.01 0.04 0.01
          }
        }
      ]
      name "ls2"
      boundingObject USE ls
      physics Physics {
      }
      occlusion TRUE
    }
    LightSensor {
      translation 0.02 0.04 -0.02
      rotation 0 1 0 0.785398
      children [
        DEF ls Shape {
          appearance Appearance {
            material Material {
              diffuseColor 1 1 0
            }
          }
          geometry Box {
            size 0.01 0.04 0.01
          }
        }
      ]
      name "ls3"
      boundingObject USE ls
      physics Physics {
      }
      occlusion TRUE
    }
    LightSensor {
      translation 0.02 0.04 0.02
      rotation 0 1 0 -0.785398
      children [
        DEF ls Shape {
          appearance Appearance {
            material Material {
              diffuseColor 1 1 0
            }
          }
          geometry Box {
            size 0.01 0.04 0.01
          }
        }
      ]
      name "ls4"
      boundingObject USE ls
      physics Physics {
      }
      occlusion TRUE
    }
    DistanceSensor {
      translation 0 0 0.1
      rotation 0 1 0 -1.5708
      children [
        DEF DS Shape {
          appearance Appearance {
            material Material {
            }
          }
          geometry Box {
            size 0.01 0.01 0.01
          }
        }
      ]
      name "ds"
      boundingObject USE DS
      physics Physics {
      }
      lookupTable [
        0 0 0
        0.2 400 0
        0.5 1000 0
      ]
    }
    HingeJoint {
      jointParameters HingeJointParameters {
        anchor -0.06 0 -0.05
      }
      device [
        DEF wheel4 RotationalMotor {
          name "wheel4"
          acceleration 1
        }
      ]
      endPoint DEF WHEEL4 Solid {
        translation -0.05999991814307717 -9.632061444724494e-06 -0.05000362374001422
        rotation 0.03312248218235521 -0.03304576865397035 0.9989048394857981 1.571866762233069
        children [
          DEF WHEEL Shape {
            appearance Appearance {
              material Material {
                diffuseColor 0 0 1
              }
            }
            geometry Cylinder {
              height 0.02
              radius 0.04
            }
          }
        ]
        name "wheel4"
        boundingObject USE WHEEL
        physics DEF WHEEL_PH Physics {
        }
      }
    }
    HingeJoint {
      jointParameters HingeJointParameters {
        anchor 0.06 0 -0.05
      }
      device [
        DEF wheel3 RotationalMotor {
          name "wheel3"
          acceleration 1
        }
      ]
      endPoint DEF WHEEL3 Solid {
        translation 0.060000176302764274 -1.3570422243021472e-05 -0.04999976121740486
        rotation 0.033052858076168264 -0.03297527418051867 0.9989094753108093 1.5718690848001053
        children [
          DEF WHEEL Shape {
            appearance Appearance {
              material Material {
                diffuseColor 0 0 1
              }
            }
            geometry Cylinder {
              height 0.02
              radius 0.04
            }
          }
        ]
        name "wheel3"
        boundingObject USE WHEEL
        physics USE WHEEL_PH
      }
    }
    HingeJoint {
      jointParameters HingeJointParameters {
        anchor -0.06 0 0.05
      }
      device [
        DEF wheel2 RotationalMotor {
          name "wheel2"
          acceleration 1
        }
      ]
      endPoint DEF WHEEL2 Solid {
        translation -0.060002157958187 -8.7540512070535e-06 0.049996310781291034
        rotation 0.033122390039492314 -0.03304586831487273 0.9989048392441533 1.5718664036508943
        children [
          DEF WHEEL Shape {
            appearance Appearance {
              material Material {
                diffuseColor 0 0 1
              }
            }
            geometry Cylinder {
              height 0.02
              radius 0.04
            }
          }
        ]
        name "wheel2"
        boundingObject USE WHEEL
        physics DEF WHEEL_PH Physics {
        }
      }
    }
    DEF BODY Shape {
      appearance Appearance {
        material Material {
          diffuseColor 1 0 0
        }
      }
      geometry Box {
        size 0.1 0.05 0.2
      }
    }
    HingeJoint {
      jointParameters HingeJointParameters {
        anchor 0.06 0 0.05
      }
      device [
        DEF wheel1 RotationalMotor {
          name "wheel1"
        }
      ]
      endPoint DEF WHEEL1 Solid {
        translation 0.06000190297626937 6.2227360664119e-06 0.049995882054905696
        rotation -0.04651496824615402 0.046637305478202655 -0.9978283015964179 4.710224110905362
        children [
          DEF WHEEL Shape {
            appearance Appearance {
              material Material {
                diffuseColor 0 0 1
              }
            }
            geometry Cylinder {
              height 0.02
              radius 0.04
            }
          }
        ]
        name "wheel1"
        boundingObject USE WHEEL
        physics USE WHEEL_PH
      }
    }
  ]
  name "RL4"
  boundingObject USE BODY
  physics Physics {
  }
  controller "AgentController_v0"
}
DEF RobotLightC6 Robot {
  translation -1.36 0.04 -2.39
  children [
    Receiver {
      name "rec1"
      channel 1
    }
    Receiver {
      name "rec2"
      channel 2
    }
    Receiver {
      name "rec3"
      channel 3
    }
    Receiver {
      name "rec4"
      channel 4
    }
    Receiver {
      name "rec5"
      channel 5
    }
    Receiver {
      name "rec7"
      channel 7
    }
    Receiver {
      name "rec8"
      channel 8
    }
    Receiver {
      name "rec9"
      channel 9
    }
    Receiver {
      name "rec6"
      channel 10
    }
    Receiver {
      name "rec10"
      channel 11
    }
    Receiver {
      name "rec11"
      channel 12
    }
    Receiver {
      name "rec12"
      channel 13
    }
    Receiver {
      name "rec13"
      channel 14
    }
    Receiver {
      name "rec14"
      channel 15
    }
    Receiver {
      name "rec15"
      channel 14
    }
    Receiver {
      translation 1.75 0 0
      name "rec16"
      channel 17
    }
    Receiver {
      translation 1.75 0 0
      name "rec17"
      channel 18
    }
    Receiver {
      translation 1.75 0 0
      name "rec18"
      channel 19
    }
    Receiver {
      translation 1.75 0 0
      name "rec19"
      channel 20
    }
    Receiver {
      translation 1.75 0 0
      name "rec20"
      channel 21
    }
    Receiver {
      translation 1.75 0 0
      name "rec21"
      channel 22
    }
    Receiver {
      translation 1.75 0 0
      name "rec22"
      channel 23
    }
    Receiver {
      translation 1.75 0 0
      name "rec23"
      channel 24
    }
    Receiver {
      translation 1.75 0 0
      name "rec24"
      channel 25
    }
    Emitter {
      name "trans"
      range 1
      maxRange 1
      channel 6
    }
    Compass {
      name "com"
      yAxis FALSE
    }
    LightSensor {
      translation -0.02 0.04 0.02
      rotation 0 1 0 -2.35619
      children [
        DEF ls Shape {
          appearance Appearance {
            material Material {
              diffuseColor 1 1 0
            }
          }
          geometry Box {
            size 0.01 0.04 0.01
          }
        }
      ]
      name "ls1"
      boundingObject USE ls
      physics Physics {
      }
      occlusion TRUE
    }
    LightSensor {
      translation -0.02 0.04 -0.02
      rotation 0 1 0 -3.92699
      children [
        DEF ls Shape {
          appearance Appearance {
            material Material {
              diffuseColor 1 1 0
            }
          }
          geometry Box {
            size 0.01 0.04 0.01
          }
        }
      ]
      name "ls2"
      boundingObject USE ls
      physics Physics {
      }
      occlusion TRUE
    }
    LightSensor {
      translation 0.02 0.04 -0.02
      rotation 0 1 0 0.785398
      children [
        DEF ls Shape {
          appearance Appearance {
            material Material {
              diffuseColor 1 1 0
            }
          }
          geometry Box {
            size 0.01 0.04 0.01
          }
        }
      ]
      name "ls3"
      boundingObject USE ls
      physics Physics {
      }
      occlusion TRUE
    }
    LightSensor {
      translation 0.02 0.04 0.02
      rotation 0 1 0 -0.785398
      children [
        DEF ls Shape {
          appearance Appearance {
            material Material {
              diffuseColor 1 1 0
            }
          }
          geometry Box {
            size 0.01 0.04 0.01
          }
        }
      ]
      name "ls4"
      boundingObject USE ls
      physics Physics {
      }
      occlusion TRUE
    }
    DistanceSensor {
      translation 0 0 0.1
      rotation 0 1 0 -1.5708
      children [
        DEF DS Shape {
          appearance Appearance {
            material Material {
            }
          }
          geometry Box {
            size 0.01 0.01 0.01
          }
        }
      ]
      name "ds"
      boundingObject USE DS
      physics Physics {
      }
      lookupTable [
        0 0 0
        0.2 400 0
        0.5 1000 0
      ]
    }
    HingeJoint {
      jointParameters HingeJointParameters {
        anchor -0.06 0 -0.05
      }
      device [
        DEF wheel4 RotationalMotor {
          name "wheel4"
          acceleration 1
        }
      ]
      endPoint DEF WHEEL4 Solid {
        translation -0.05999991814307717 -9.632061444724495e-06 -0.05000362374001422
        rotation 0.0331224821823552 -0.03304576865397035 0.9989048394857979 1.5718667622330686
        children [
          DEF WHEEL Shape {
            appearance Appearance {
              material Material {
                diffuseColor 0 0 1
              }
            }
            geometry Cylinder {
              height 0.02
              radius 0.04
            }
          }
        ]
        name "wheel4"
        boundingObject USE WHEEL
        physics DEF WHEEL_PH Physics {
        }
      }
    }
    HingeJoint {
      jointParameters HingeJointParameters {
        anchor 0.06 0 -0.05
      }
      device [
        DEF wheel3 RotationalMotor {
          name "wheel3"
          acceleration 1
        }
      ]
      endPoint DEF WHEEL3 Solid {
        translation 0.060000176302764274 -1.357042224302147e-05 -0.04999976121740486
        rotation 0.033052858076168264 -0.03297527418051867 0.9989094753108093 1.5718690848001053
        children [
          DEF WHEEL Shape {
            appearance Appearance {
              material Material {
                diffuseColor 0 0 1
              }
            }
            geometry Cylinder {
              height 0.02
              radius 0.04
            }
          }
        ]
        name "wheel3"
        boundingObject USE WHEEL
        physics USE WHEEL_PH
      }
    }
    HingeJoint {
      jointParameters HingeJointParameters {
        anchor -0.06 0 0.05
      }
      device [
        DEF wheel2 RotationalMotor {
          name "wheel2"
          acceleration 1
        }
      ]
      endPoint DEF WHEEL2 Solid {
        translation -0.060002157958187 -8.754051207053491e-06 0.049996310781291034
        rotation 0.033122390039492335 -0.033045868314872745 0.9989048392441533 1.5718664036508943
        children [
          DEF WHEEL Shape {
            appearance Appearance {
              material Material {
                diffuseColor 0 0 1
              }
            }
            geometry Cylinder {
              height 0.02
              radius 0.04
            }
          }
        ]
        name "wheel2"
        boundingObject USE WHEEL
        physics DEF WHEEL_PH Physics {
        }
      }
    }
    DEF BODY Shape {
      appearance Appearance {
        material Material {
          diffuseColor 1 0 0
        }
      }
      geometry Box {
        size 0.1 0.05 0.2
      }
    }
    HingeJoint {
      jointParameters HingeJointParameters {
        anchor 0.06 0 0.05
      }
      device [
        DEF wheel1 RotationalMotor {
          name "wheel1"
        }
      ]
      endPoint DEF WHEEL1 Solid {
        translation 0.06000190297626937 6.22273606641257e-06 0.049995882054905696
        rotation -0.04651496824615402 0.04663730547820272 -0.9978283015964179 4.710224110905362
        children [
          DEF WHEEL Shape {
            appearance Appearance {
              material Material {
                diffuseColor 0 0 1
              }
            }
            geometry Cylinder {
              height 0.02
              radius 0.04
            }
          }
        ]
        name "wheel1"
        boundingObject USE WHEEL
        physics USE WHEEL_PH
      }
    }
  ]
  name "RL5"
  boundingObject USE BODY
  physics Physics {
  }
  controller "AgentController_v0"
}
DEF RobotLightC7 Robot {
  translation 1.61 0.04 -2.48
  children [
    Receiver {
      name "rec1"
      channel 1
    }
    Receiver {
      name "rec2"
      channel 2
    }
    Receiver {
      name "rec3"
      channel 3
    }
    Receiver {
      name "rec4"
      channel 4
    }
    Receiver {
      name "rec5"
      channel 5
    }
    Receiver {
      name "rec6"
      channel 6
    }
    Receiver {
      name "rec8"
      channel 8
    }
    Receiver {
      name "rec9"
      channel 9
    }
    Receiver {
      name "rec7"
      channel 10
    }
    Receiver {
      name "rec10"
      channel 11
    }
    Receiver {
      name "rec11"
      channel 12
    }
    Receiver {
      name "rec12"
      channel 13
    }
    Receiver {
      name "rec13"
      channel 14
    }
    Receiver {
      name "rec14"
      channel 15
    }
    Receiver {
      name "rec15"
      channel 14
    }
    Receiver {
      translation 1.75 0 0
      name "rec16"
      channel 17
    }
    Receiver {
      translation 1.75 0 0
      name "rec17"
      channel 18
    }
    Receiver {
      translation 1.75 0 0
      name "rec18"
      channel 19
    }
    Receiver {
      translation 1.75 0 0
      name "rec19"
      channel 20
    }
    Receiver {
      translation 1.75 0 0
      name "rec20"
      channel 21
    }
    Receiver {
      translation 1.75 0 0
      name "rec21"
      channel 22
    }
    Receiver {
      translation 1.75 0 0
      name "rec22"
      channel 23
    }
    Receiver {
      translation 1.75 0 0
      name "rec23"
      channel 24
    }
    Receiver {
      translation 1.75 0 0
      name "rec24"
      channel 25
    }
    Emitter {
      name "trans"
      range 1
      maxRange 1
      channel 7
    }
    Compass {
      name "com"
      yAxis FALSE
    }
    LightSensor {
      translation -0.02 0.04 0.02
      rotation 0 1 0 -2.35619
      children [
        DEF ls Shape {
          appearance Appearance {
            material Material {
              diffuseColor 1 1 0
            }
          }
          geometry Box {
            size 0.01 0.04 0.01
          }
        }
      ]
      name "ls1"
      boundingObject USE ls
      physics Physics {
      }
      occlusion TRUE
    }
    LightSensor {
      translation -0.02 0.04 -0.02
      rotation 0 1 0 -3.92699
      children [
        DEF ls Shape {
          appearance Appearance {
            material Material {
              diffuseColor 1 1 0
            }
          }
          geometry Box {
            size 0.01 0.04 0.01
          }
        }
      ]
      name "ls2"
      boundingObject USE ls
      physics Physics {
      }
      occlusion TRUE
    }
    LightSensor {
      translation 0.02 0.04 -0.02
      rotation 0 1 0 0.785398
      children [
        DEF ls Shape {
          appearance Appearance {
            material Material {
              diffuseColor 1 1 0
            }
          }
          geometry Box {
            size 0.01 0.04 0.01
          }
        }
      ]
      name "ls3"
      boundingObject USE ls
      physics Physics {
      }
      occlusion TRUE
    }
    LightSensor {
      translation 0.02 0.04 0.02
      rotation 0 1 0 -0.785398
      children [
        DEF ls Shape {
          appearance Appearance {
            material Material {
              diffuseColor 1 1 0
            }
          }
          geometry Box {
            size 0.01 0.04 0.01
          }
        }
      ]
      name "ls4"
      boundingObject USE ls
      physics Physics {
      }
      occlusion TRUE
    }
    DistanceSensor {
      translation 0 0 0.1
      rotation 0 1 0 -1.5708
      children [
        DEF DS Shape {
          appearance Appearance {
            material Material {
            }
          }
          geometry Box {
            size 0.01 0.01 0.01
          }
        }
      ]
      name "ds"
      boundingObject USE DS
      physics Physics {
      }
      lookupTable [
        0 0 0
        0.2 400 0
        0.5 1000 0
      ]
    }
    HingeJoint {
      jointParameters HingeJointParameters {
        anchor -0.06 0 -0.05
      }
      device [
        DEF wheel4 RotationalMotor {
          name "wheel4"
          acceleration 1
        }
      ]
      endPoint DEF WHEEL4 Solid {
        translation -0.05999991814307717 -9.632061444724494e-06 -0.05000362374001422
        rotation 0.03312248218235521 -0.03304576865397035 0.9989048394857981 1.571866762233069
        children [
          DEF WHEEL Shape {
            appearance Appearance {
              material Material {
                diffuseColor 0 0 1
              }
            }
            geometry Cylinder {
              height 0.02
              radius 0.04
            }
          }
        ]
        name "wheel4"
        boundingObject USE WHEEL
        physics DEF WHEEL_PH Physics {
        }
      }
    }
    HingeJoint {
      jointParameters HingeJointParameters {
        anchor 0.06 0 -0.05
      }
      device [
        DEF wheel3 RotationalMotor {
          name "wheel3"
          acceleration 1
        }
      ]
      endPoint DEF WHEEL3 Solid {
        translation 0.060000176302764274 -1.3570422243021472e-05 -0.04999976121740486
        rotation 0.033052858076168264 -0.03297527418051867 0.9989094753108093 1.5718690848001053
        children [
          DEF WHEEL Shape {
            appearance Appearance {
              material Material {
                diffuseColor 0 0 1
              }
            }
            geometry Cylinder {
              height 0.02
              radius 0.04
            }
          }
        ]
        name "wheel3"
        boundingObject USE WHEEL
        physics USE WHEEL_PH
      }
    }
    HingeJoint {
      jointParameters HingeJointParameters {
        anchor -0.06 0 0.05
      }
      device [
        DEF wheel2 RotationalMotor {
          name "wheel2"
          acceleration 1
        }
      ]
      endPoint DEF WHEEL2 Solid {
        translation -0.060002157958187 -8.7540512070535e-06 0.049996310781291034
        rotation 0.033122390039492314 -0.03304586831487273 0.9989048392441533 1.5718664036508943
        children [
          DEF WHEEL Shape {
            appearance Appearance {
              material Material {
                diffuseColor 0 0 1
              }
            }
            geometry Cylinder {
              height 0.02
              radius 0.04
            }
          }
        ]
        name "wheel2"
        boundingObject USE WHEEL
        physics DEF WHEEL_PH Physics {
        }
      }
    }
    DEF BODY Shape {
      appearance Appearance {
        material Material {
          diffuseColor 1 0 0
        }
      }
      geometry Box {
        size 0.1 0.05 0.2
      }
    }
    HingeJoint {
      jointParameters HingeJointParameters {
        anchor 0.06 0 0.05
      }
      device [
        DEF wheel1 RotationalMotor {
          name "wheel1"
        }
      ]
      endPoint DEF WHEEL1 Solid {
        translation 0.06000190297626937 6.2227360664119e-06 0.049995882054905696
        rotation -0.04651496824615402 0.046637305478202655 -0.9978283015964179 4.710224110905362
        children [
          DEF WHEEL Shape {
            appearance Appearance {
              material Material {
                diffuseColor 0 0 1
              }
            }
            geometry Cylinder {
              height 0.02
              radius 0.04
            }
          }
        ]
        name "wheel1"
        boundingObject USE WHEEL
        physics USE WHEEL_PH
      }
    }
  ]
  name "RL6"
  boundingObject USE BODY
  physics Physics {
  }
  controller "AgentController_v0"
}
DEF RobotLightC8 Robot {
  translation -0.88 0.04 -2.44
  children [
    Receiver {
      name "rec1"
      channel 1
    }
    Receiver {
      name "rec2"
      channel 2
    }
    Receiver {
      name "rec3"
      channel 3
    }
    Receiver {
      name "rec4"
      channel 4
    }
    Receiver {
      name "rec5"
      channel 5
    }
    Receiver {
      name "rec6"
      channel 6
    }
    Receiver {
      name "rec7"
      channel 7
    }
    Receiver {
      name "rec9"
      channel 9
    }
    Receiver {
      name "rec8"
      channel 10
    }
    Receiver {
      name "rec10"
      channel 11
    }
    Receiver {
      name "rec11"
      channel 12
    }
    Receiver {
      name "rec12"
      channel 13
    }
    Receiver {
      name "rec13"
      channel 14
    }
    Receiver {
      name "rec14"
      channel 15
    }
    Receiver {
      name "rec15"
      channel 14
    }
    Receiver {
      translation 1.75 0 0
      name "rec16"
      channel 17
    }
    Receiver {
      translation 1.75 0 0
      name "rec17"
      channel 18
    }
    Receiver {
      translation 1.75 0 0
      name "rec18"
      channel 19
    }
    Receiver {
      translation 1.75 0 0
      name "rec19"
      channel 20
    }
    Receiver {
      translation 1.75 0 0
      name "rec20"
      channel 21
    }
    Receiver {
      translation 1.75 0 0
      name "rec21"
      channel 22
    }
    Receiver {
      translation 1.75 0 0
      name "rec22"
      channel 23
    }
    Receiver {
      translation 1.75 0 0
      name "rec23"
      channel 24
    }
    Receiver {
      translation 1.75 0 0
      name "rec24"
      channel 25
    }
    Emitter {
      name "trans"
      range 1
      maxRange 1
      channel 8
    }
    Compass {
      name "com"
      yAxis FALSE
    }
    LightSensor {
      translation -0.02 0.04 0.02
      rotation 0 1 0 -2.35619
      children [
        DEF ls Shape {
          appearance Appearance {
            material Material {
              diffuseColor 1 1 0
            }
          }
          geometry Box {
            size 0.01 0.04 0.01
          }
        }
      ]
      name "ls1"
      boundingObject USE ls
      physics Physics {
      }
      occlusion TRUE
    }
    LightSensor {
      translation -0.02 0.04 -0.02
      rotation 0 1 0 -3.92699
      children [
        DEF ls Shape {
          appearance Appearance {
            material Material {
              diffuseColor 1 1 0
            }
          }
          geometry Box {
            size 0.01 0.04 0.01
          }
        }
      ]
      name "ls2"
      boundingObject USE ls
      physics Physics {
      }
      occlusion TRUE
    }
    LightSensor {
      translation 0.02 0.04 -0.02
      rotation 0 1 0 0.785398
      children [
        DEF ls Shape {
          appearance Appearance {
            material Material {
              diffuseColor 1 1 0
            }
          }
          geometry Box {
            size 0.01 0.04 0.01
          }
        }
      ]
      name "ls3"
      boundingObject USE ls
      physics Physics {
      }
      occlusion TRUE
    }
    LightSensor {
      translation 0.02 0.04 0.02
      rotation 0 1 0 -0.785398
      children [
        DEF ls Shape {
          appearance Appearance {
            material Material {
              diffuseColor 1 1 0
            }
          }
          geometry Box {
            size 0.01 0.04 0.01
          }
        }
      ]
      name "ls4"
      boundingObject USE ls
      physics Physics {
      }
      occlusion TRUE
    }
    DistanceSensor {
      translation 0 0 0.1
      rotation 0 1 0 -1.5708
      children [
        DEF DS Shape {
          appearance Appearance {
            material Material {
            }
          }
          geometry Box {
            size 0.01 0.01 0.01
          }
        }
      ]
      name "ds"
      boundingObject USE DS
      physics Physics {
      }
      lookupTable [
        0 0 0
        0.2 400 0
        0.5 1000 0
      ]
    }
    HingeJoint {
      jointParameters HingeJointParameters {
        anchor -0.06 0 -0.05
      }
      device [
        DEF wheel4 RotationalMotor {
          name "wheel4"
          acceleration 1
        }
      ]
      endPoint DEF WHEEL4 Solid {
        translation -0.059975191505796915 0.00024125326843214145 -0.049759154313492565
        rotation -0.7051347974440975 -0.07474096682424686 0.7051231844944884 2.9922724403232497
        children [
          DEF WHEEL Shape {
            appearance Appearance {
              material Material {
                diffuseColor 0 0 1
              }
            }
            geometry Cylinder {
              height 0.02
              radius 0.04
            }
          }
        ]
        name "wheel4"
        boundingObject USE WHEEL
        physics DEF WHEEL_PH Physics {
        }
      }
    }
    HingeJoint {
      jointParameters HingeJointParameters {
        anchor 0.06 0 -0.05
      }
      device [
        DEF wheel3 RotationalMotor {
          name "wheel3"
          acceleration 1
        }
      ]
      endPoint DEF WHEEL3 Solid {
        translation 0.060000176302764274 -1.3570422243026116e-05 -0.04999976121740486
        rotation 0.03305285807616829 -0.03297527418051867 0.9989094753108093 1.5718690848001058
        children [
          DEF WHEEL Shape {
            appearance Appearance {
              material Material {
                diffuseColor 0 0 1
              }
            }
            geometry Cylinder {
              height 0.02
              radius 0.04
            }
          }
        ]
        name "wheel3"
        boundingObject USE WHEEL
        physics USE WHEEL_PH
      }
    }
    HingeJoint {
      jointParameters HingeJointParameters {
        anchor -0.06 0 0.05
      }
      device [
        DEF wheel2 RotationalMotor {
          name "wheel2"
          acceleration 1
        }
      ]
      endPoint DEF WHEEL2 Solid {
        translation -0.060002157958187 -8.754051207050896e-06 0.049996310781291034
        rotation 0.0331223900394925 -0.03304586831487268 0.9989048392441534 1.5718664036508947
        children [
          DEF WHEEL Shape {
            appearance Appearance {
              material Material {
                diffuseColor 0 0 1
              }
            }
            geometry Cylinder {
              height 0.02
              radius 0.04
            }
          }
        ]
        name "wheel2"
        boundingObject USE WHEEL
        physics DEF WHEEL_PH Physics {
        }
      }
    }
    DEF BODY Shape {
      appearance Appearance {
        material Material {
          diffuseColor 1 0 0
        }
      }
      geometry Box {
        size 0.1 0.05 0.2
      }
    }
    HingeJoint {
      jointParameters HingeJointParameters {
        anchor 0.06 0 0.05
      }
      device [
        DEF wheel1 RotationalMotor {
          name "wheel1"
        }
      ]
      endPoint DEF WHEEL1 Solid {
        translation 0.06000190297626937 6.222736066409942e-06 0.049995882054905696
        rotation -0.04651496824615379 0.04663730547820255 -0.997828301596418 4.710224110905363
        children [
          DEF WHEEL Shape {
            appearance Appearance {
              material Material {
                diffuseColor 0 0 1
              }
            }
            geometry Cylinder {
              height 0.02
              radius 0.04
            }
          }
        ]
        name "wheel1"
        boundingObject USE WHEEL
        physics USE WHEEL_PH
      }
    }
  ]
  name "RL7"
  boundingObject USE BODY
  physics Physics {
  }
  controller "AgentController_v0"
}
DEF RobotLightC9 Robot {
  translation 3.09 0.04 -2.4
  children [
    Receiver {
      name "rec1"
      channel 1
    }
    Receiver {
      name "rec2"
      channel 2
    }
    Receiver {
      name "rec3"
      channel 3
    }
    Receiver {
      name "rec4"
      channel 4
    }
    Receiver {
      name "rec5"
      channel 5
    }
    Receiver {
      name "rec6"
      channel 6
    }
    Receiver {
      name "rec7"
      channel 7
    }
    Receiver {
      name "rec8"
      channel 8
    }
    Receiver {
      name "rec9"
      channel 10
    }
    Receiver {
      name "rec10"
      channel 11
    }
    Receiver {
      name "rec11"
      channel 12
    }
    Receiver {
      name "rec12"
      channel 13
    }
    Receiver {
      name "rec13"
      channel 14
    }
    Receiver {
      name "rec14"
      channel 15
    }
    Receiver {
      name "rec15"
      channel 14
    }
    Receiver {
      translation 1.75 0 0
      name "rec16"
      channel 17
    }
    Receiver {
      translation 1.75 0 0
      name "rec17"
      channel 18
    }
    Receiver {
      translation 1.75 0 0
      name "rec18"
      channel 19
    }
    Receiver {
      translation 1.75 0 0
      name "rec19"
      channel 20
    }
    Receiver {
      translation 1.75 0 0
      name "rec20"
      channel 21
    }
    Receiver {
      translation 1.75 0 0
      name "rec21"
      channel 22
    }
    Receiver {
      translation 1.75 0 0
      name "rec22"
      channel 23
    }
    Receiver {
      translation 1.75 0 0
      name "rec23"
      channel 24
    }
    Receiver {
      translation 1.75 0 0
      name "rec24"
      channel 25
    }
    Emitter {
      name "trans"
      range 1
      maxRange 1
      channel 9
    }
    Compass {
      name "com"
      yAxis FALSE
    }
    LightSensor {
      translation -0.02 0.04 0.02
      rotation 0 1 0 -2.35619
      children [
        DEF ls Shape {
          appearance Appearance {
            material Material {
              diffuseColor 1 1 0
            }
          }
          geometry Box {
            size 0.01 0.04 0.01
          }
        }
      ]
      name "ls1"
      boundingObject USE ls
      physics Physics {
      }
      occlusion TRUE
    }
    LightSensor {
      translation -0.02 0.04 -0.02
      rotation 0 1 0 -3.92699
      children [
        DEF ls Shape {
          appearance Appearance {
            material Material {
              diffuseColor 1 1 0
            }
          }
          geometry Box {
            size 0.01 0.04 0.01
          }
        }
      ]
      name "ls2"
      boundingObject USE ls
      physics Physics {
      }
      occlusion TRUE
    }
    LightSensor {
      translation 0.02 0.04 -0.02
      rotation 0 1 0 0.785398
      children [
        DEF ls Shape {
          appearance Appearance {
            material Material {
              diffuseColor 1 1 0
            }
          }
          geometry Box {
            size 0.01 0.04 0.01
          }
        }
      ]
      name "ls3"
      boundingObject USE ls
      physics Physics {
      }
      occlusion TRUE
    }
    LightSensor {
      translation 0.02 0.04 0.02
      rotation 0 1 0 -0.785398
      children [
        DEF ls Shape {
          appearance Appearance {
            material Material {
              diffuseColor 1 1 0
            }
          }
          geometry Box {
            size 0.01 0.04 0.01
          }
        }
      ]
      name "ls4"
      boundingObject USE ls
      physics Physics {
      }
      occlusion TRUE
    }
    DistanceSensor {
      translation 0 0 0.1
      rotation 0 1 0 -1.5708
      children [
        DEF DS Shape {
          appearance Appearance {
            material Material {
            }
          }
          geometry Box {
            size 0.01 0.01 0.01
          }
        }
      ]
      name "ds"
      boundingObject USE DS
      physics Physics {
      }
      lookupTable [
        0 0 0
        0.2 400 0
        0.5 1000 0
      ]
    }
    HingeJoint {
      jointParameters HingeJointParameters {
        anchor -0.06 0 -0.05
      }
      device [
        DEF wheel4 RotationalMotor {
          name "wheel4"
          acceleration 1
        }
      ]
      endPoint DEF WHEEL4 Solid {
        translation -0.05999991814307717 -9.632061444724494e-06 -0.05000362374001422
        rotation 0.03312248218235521 -0.03304576865397035 0.9989048394857981 1.571866762233069
        children [
          DEF WHEEL Shape {
            appearance Appearance {
              material Material {
                diffuseColor 0 0 1
              }
            }
            geometry Cylinder {
              height 0.02
              radius 0.04
            }
          }
        ]
        name "wheel4"
        boundingObject USE WHEEL
        physics DEF WHEEL_PH Physics {
        }
      }
    }
    HingeJoint {
      jointParameters HingeJointParameters {
        anchor 0.06 0 -0.05
      }
      device [
        DEF wheel3 RotationalMotor {
          name "wheel3"
          acceleration 1
        }
      ]
      endPoint DEF WHEEL3 Solid {
        translation 0.060000176302764274 -1.3570422243021472e-05 -0.04999976121740486
        rotation 0.033052858076168264 -0.03297527418051867 0.9989094753108093 1.5718690848001053
        children [
          DEF WHEEL Shape {
            appearance Appearance {
              material Material {
                diffuseColor 0 0 1
              }
            }
            geometry Cylinder {
              height 0.02
              radius 0.04
            }
          }
        ]
        name "wheel3"
        boundingObject USE WHEEL
        physics USE WHEEL_PH
      }
    }
    HingeJoint {
      jointParameters HingeJointParameters {
        anchor -0.06 0 0.05
      }
      device [
        DEF wheel2 RotationalMotor {
          name "wheel2"
          acceleration 1
        }
      ]
      endPoint DEF WHEEL2 Solid {
        translation -0.060002157958187 -8.7540512070535e-06 0.049996310781291034
        rotation 0.033122390039492314 -0.03304586831487273 0.9989048392441533 1.5718664036508943
        children [
          DEF WHEEL Shape {
            appearance Appearance {
              material Material {
                diffuseColor 0 0 1
              }
            }
            geometry Cylinder {
              height 0.02
              radius 0.04
            }
          }
        ]
        name "wheel2"
        boundingObject USE WHEEL
        physics DEF WHEEL_PH Physics {
        }
      }
    }
    DEF BODY Shape {
      appearance Appearance {
        material Material {
          diffuseColor 1 0 0
        }
      }
      geometry Box {
        size 0.1 0.05 0.2
      }
    }
    HingeJoint {
      jointParameters HingeJointParameters {
        anchor 0.06 0 0.05
      }
      device [
        DEF wheel1 RotationalMotor {
          name "wheel1"
        }
      ]
      endPoint DEF WHEEL1 Solid {
        translation 0.06000190297626937 6.2227360664119e-06 0.049995882054905696
        rotation -0.04651496824615402 0.046637305478202655 -0.9978283015964179 4.710224110905362
        children [
          DEF WHEEL Shape {
            appearance Appearance {
              material Material {
                diffuseColor 0 0 1
              }
            }
            geometry Cylinder {
              height 0.02
              radius 0.04
            }
          }
        ]
        name "wheel1"
        boundingObject USE WHEEL
        physics USE WHEEL_PH
      }
    }
  ]
  name "RL8"
  boundingObject USE BODY
  physics Physics {
  }
  controller "AgentController_v0"
}
DEF RobotLightC10 Robot {
  translation 2.6 0.04 -2.47
  children [
    Receiver {
      name "rec1"
      channel 1
    }
    Receiver {
      name "rec2"
      channel 2
    }
    Receiver {
      name "rec3"
      channel 3
    }
    Receiver {
      name "rec4"
      channel 4
    }
    Receiver {
      name "rec5"
      channel 5
    }
    Receiver {
      name "rec6"
      channel 6
    }
    Receiver {
      name "rec7"
      channel 7
    }
    Receiver {
      name "rec8"
      channel 8
    }
    Receiver {
      name "rec9"
      channel 9
    }
    Receiver {
      name "rec10"
      channel 11
    }
    Receiver {
      name "rec11"
      channel 12
    }
    Receiver {
      name "rec12"
      channel 13
    }
    Receiver {
      name "rec13"
      channel 14
    }
    Receiver {
      name "rec14"
      channel 15
    }
    Receiver {
      name "rec15"
      channel 14
    }
    Receiver {
      translation 1.75 0 0
      name "rec16"
      channel 17
    }
    Receiver {
      translation 1.75 0 0
      name "rec17"
      channel 18
    }
    Receiver {
      translation 1.75 0 0
      name "rec18"
      channel 19
    }
    Receiver {
      translation 1.75 0 0
      name "rec19"
      channel 20
    }
    Receiver {
      translation 1.75 0 0
      name "rec20"
      channel 21
    }
    Receiver {
      translation 1.75 0 0
      name "rec21"
      channel 22
    }
    Receiver {
      translation 1.75 0 0
      name "rec22"
      channel 23
    }
    Receiver {
      translation 1.75 0 0
      name "rec23"
      channel 24
    }
    Receiver {
      translation 1.75 0 0
      name "rec24"
      channel 25
    }
    Emitter {
      name "trans"
      range 1
      maxRange 1
      channel 10
    }
    Compass {
      name "com"
      yAxis FALSE
    }
    LightSensor {
      translation -0.02 0.04 0.02
      rotation 0 1 0 -2.35619
      children [
        DEF ls Shape {
          appearance Appearance {
            material Material {
              diffuseColor 1 1 0
            }
          }
          geometry Box {
            size 0.01 0.04 0.01
          }
        }
      ]
      name "ls1"
      boundingObject USE ls
      physics Physics {
      }
      occlusion TRUE
    }
    LightSensor {
      translation -0.02 0.04 -0.02
      rotation 0 1 0 -3.92699
      children [
        DEF ls Shape {
          appearance Appearance {
            material Material {
              diffuseColor 1 1 0
            }
          }
          geometry Box {
            size 0.01 0.04 0.01
          }
        }
      ]
      name "ls2"
      boundingObject USE ls
      physics Physics {
      }
      occlusion TRUE
    }
    LightSensor {
      translation 0.02 0.04 -0.02
      rotation 0 1 0 0.785398
      children [
        DEF ls Shape {
          appearance Appearance {
            material Material {
              diffuseColor 1 1 0
            }
          }
          geometry Box {
            size 0.01 0.04 0.01
          }
        }
      ]
      name "ls3"
      boundingObject USE ls
      physics Physics {
      }
      occlusion TRUE
    }
    LightSensor {
      translation 0.02 0.04 0.02
      rotation 0 1 0 -0.785398
      children [
        DEF ls Shape {
          appearance Appearance {
            material Material {
              diffuseColor 1 1 0
            }
          }
          geometry Box {
            size 0.01 0.04 0.01
          }
        }
      ]
      name "ls4"
      boundingObject USE ls
      physics Physics {
      }
      occlusion TRUE
    }
    DistanceSensor {
      translation 0 0 0.1
      rotation 0 1 0 -1.5708
      children [
        DEF DS Shape {
          appearance Appearance {
            material Material {
            }
          }
          geometry Box {
            size 0.01 0.01 0.01
          }
        }
      ]
      name "ds"
      boundingObject USE DS
      physics Physics {
      }
      lookupTable [
        0 0 0
        0.2 400 0
        0.5 1000 0
      ]
    }
    HingeJoint {
      jointParameters HingeJointParameters {
        anchor -0.06 0 -0.05
      }
      device [
        DEF wheel4 RotationalMotor {
          name "wheel4"
          acceleration 1
        }
      ]
      endPoint DEF WHEEL4 Solid {
        translation -0.05999991814307717 -9.632061444724494e-06 -0.05000362374001422
        rotation 0.03312248218235521 -0.03304576865397035 0.9989048394857981 1.571866762233069
        children [
          DEF WHEEL Shape {
            appearance Appearance {
              material Material {
                diffuseColor 0 0 1
              }
            }
            geometry Cylinder {
              height 0.02
              radius 0.04
            }
          }
        ]
        name "wheel4"
        boundingObject USE WHEEL
        physics DEF WHEEL_PH Physics {
        }
      }
    }
    HingeJoint {
      jointParameters HingeJointParameters {
        anchor 0.06 0 -0.05
      }
      device [
        DEF wheel3 RotationalMotor {
          name "wheel3"
          acceleration 1
        }
      ]
      endPoint DEF WHEEL3 Solid {
        translation 0.060000176302764274 -1.3570422243021472e-05 -0.04999976121740486
        rotation 0.033052858076168264 -0.03297527418051867 0.9989094753108093 1.5718690848001053
        children [
          DEF WHEEL Shape {
            appearance Appearance {
              material Material {
                diffuseColor 0 0 1
              }
            }
            geometry Cylinder {
              height 0.02
              radius 0.04
            }
          }
        ]
        name "wheel3"
        boundingObject USE WHEEL
        physics USE WHEEL_PH
      }
    }
    HingeJoint {
      jointParameters HingeJointParameters {
        anchor -0.06 0 0.05
      }
      device [
        DEF wheel2 RotationalMotor {
          name "wheel2"
          acceleration 1
        }
      ]
      endPoint DEF WHEEL2 Solid {
        translation -0.060002157958187 -8.7540512070535e-06 0.049996310781291034
        rotation 0.033122390039492314 -0.03304586831487273 0.9989048392441533 1.5718664036508943
        children [
          DEF WHEEL Shape {
            appearance Appearance {
              material Material {
                diffuseColor 0 0 1
              }
            }
            geometry Cylinder {
              height 0.02
              radius 0.04
            }
          }
        ]
        name "wheel2"
        boundingObject USE WHEEL
        physics DEF WHEEL_PH Physics {
        }
      }
    }
    DEF BODY Shape {
      appearance Appearance {
        material Material {
          diffuseColor 1 0 0
        }
      }
      geometry Box {
        size 0.1 0.05 0.2
      }
    }
    HingeJoint {
      jointParameters HingeJointParameters {
        anchor 0.06 0 0.05
      }
      device [
        DEF wheel1 RotationalMotor {
          name "wheel1"
        }
      ]
      endPoint DEF WHEEL1 Solid {
        translation 0.06000190297626937 6.2227360664119e-06 0.049995882054905696
        rotation -0.04651496824615402 0.046637305478202655 -0.9978283015964179 4.710224110905362
        children [
          DEF WHEEL Shape {
            appearance Appearance {
              material Material {
                diffuseColor 0 0 1
              }
            }
            geometry Cylinder {
              height 0.02
              radius 0.04
            }
          }
        ]
        name "wheel1"
        boundingObject USE WHEEL
        physics USE WHEEL_PH
      }
    }
  ]
  name "RL9"
  boundingObject USE BODY
  physics Physics {
  }
  controller "AgentController_v0"
}
SolidPipe {
  translation 2.41 0 -0.85
  height 1
  thickness 0.99
  appearance PBRAppearance {
    baseColorMap ImageTexture {
      url [
        "textures/asphalt.jpg"
      ]
    }
    roughness 0.5
    metalness 0
  }
}
SolidPipe {
  translation -1.77952 -5.32907e-14 -0.200659
  name "pipe(1)"
  height 1
  thickness 0.99
  appearance PBRAppearance {
    baseColorMap ImageTexture {
      url [
        "textures/asphalt.jpg"
      ]
    }
    roughness 0.5
    metalness 0
  }
}
